<?xml version="1.0"?>
<robot xmlns:xacro="http://ros.org/wiki/xacro" name="chassis_macro">
  <xacro:macro name="chassis_macro" params="name parent_link x_offset:=0 y_offset:=0 z_offset:=0">
    <link name="${name}">
      <inertial>
        <origin xyz="0.45171 -1.9114E-06 -0.0060107" rpy="0 0 0" />
        <mass value="120.39" />
        <inertia ixx="0.44337" ixy="0.00087842" ixz="-0.12544" iyy="31.837" iyz="-2.5044E-05" izz="31.906" />
      </inertial>
      <visual>
        <origin xyz="0 0 0" rpy="0 0 0" />
        <geometry>
          <mesh filename="package://rr_robot_description/include/chassis/meshes/Chassis/visual.STL" />
        </geometry>
        <material name="rr_blue">
          <color rgba="0 0.62352941176 0.89019607843 1" />
        </material>
      </visual>
      <!-- <collision>
        <origin xyz="0 0 0" rpy="0 0 0" />
        <geometry>
          <mesh filename="package://rr_robot_description/include/chassis/meshes/Chassis/collision.STL" />
        </geometry>
      </collision> -->
    </link>

    <joint name="${parent_link}_to_${name}" type="fixed">
      <parent link="${parent_link}"/>
      <child link="${name}" />
      <origin xyz="${x_offset} ${y_offset} ${z_offset}" rpy="0 0 0" />
    </joint>

    <!-- ******************** IMU ******************************* -->

    <!-- imu link -->
    <link name="imu_link">
      <inertial>
        <mass value="0.1" />
        <origin xyz="0 0 0" rpy="0 0 0" />
        <inertia ixx="0.0001" ixy="0" ixz="0" iyy="0.0001" iyz="0" izz="0.0001"/>
      </inertial>
      <visual>
        <origin xyz="0 0 0" rpy="0 0 0" />
        <geometry>
          <box size="0.03 0.03 0.03" />
        </geometry>
        <material name="grey">
          <color rgba="0.4 0.4 0.4 1" />
        </material>
      </visual>
      <collision>
        <origin xyz="0 0 0" rpy="0 0 0" />
        <geometry>
          <box size="0.03 0.03 0.03" />
        </geometry>
      </collision>
    </link>
    <joint name="imu_joint" type="fixed">
      <origin xyz="0.9 -0.035 0.093" rpy="0 ${pi} 0"/>
      <parent link="${name}"/>
      <child link="imu_link"/>
    </joint>

    <!-- ********************* Rope Drives ********************** -->

    <link name="rope_drive_le">
      <inertial>
        <mass value="2.206" />
        <origin xyz="0 0 0" rpy="0 0 0" />
        <inertia ixx="0.00699387" ixy="0" ixz="0" iyy="0.0044146" iyz="0" izz="0.0044146"/>
      </inertial>
      <visual>
        <origin xyz="0 0 0" rpy="0 0 0" />
        <geometry>
          <mesh filename="package://rr_robot_description/include/chassis/meshes/RopeDrives/visual.STL" />
        </geometry>
        <material name="grey">
          <color rgba="0.4 0.4 0.4 1" />
        </material>
      </visual>
      <collision>
        <origin xyz="0 0 0" rpy="0 0 0" />
        <geometry>
          <mesh filename="package://rr_robot_description/include/chassis/meshes/RopeDrives/collision.STL" />
        </geometry>
      </collision>
    </link>
    <joint name="rope_drive_le_joint" type="continuous">
      <origin xyz="0.92999 0.24067 -0.0269" rpy="-0.09857 0.09857 -1.64405" />
      <axis rpy="0 0 0" xyz="1 0 0" />
      <limit effort="10000" velocity="1000" />
      <joint_properties damping="1.0" friction="1.0" />
      <parent link="${name}" />
      <child link="rope_drive_le" />
    </joint>

    <link name="rope_drive_te">
      <inertial>
        <mass value="2.206" />
        <origin xyz="0 0 0" rpy="0 0 0" />
        <inertia ixx="0.00699387" ixy="0" ixz="0" iyy="0.0044146" iyz="0" izz="0.0044146"/>
      </inertial>
      <visual>
        <origin xyz="0 0 0" rpy="0 0 0" />
        <geometry>
          <mesh filename="package://rr_robot_description/include/chassis/meshes/RopeDrives/visual.STL" />
        </geometry>
        <material name="grey">
          <color rgba="0.4 0.4 0.4 1" />
        </material>
      </visual>
      <collision>
        <origin xyz="0 0 0" rpy="0 0 0" />
        <geometry>
          <mesh filename="package://rr_robot_description/include/chassis/meshes/RopeDrives/collision.STL" />
        </geometry>
      </collision>
    </link>
    <joint name="rope_drive_te_joint" type="continuous">
      <origin xyz="0.92999 -0.24067 -0.0269" rpy="0.09857 0.09857 1.64405" />
      <axis rpy="0 0 0" xyz="-1 0 0" />
      <limit effort="10000" velocity="1000" />
      <joint_properties damping="1.0" friction="1.0" />
      <parent link="${name}" />
      <child link="rope_drive_te" />
    </joint>

    <!-- ********************* Vacuum Sheet ********************* -->

    <link name="vacuum_sheet">
      <inertial>
        <mass value="0.6" />
        <origin xyz="0 0 0" rpy="0 0 0" />
        <inertia ixx="0.0025275579" ixy="0" ixz="0" iyy="0.00001388" iyz="0" izz="0.04124286"/>
      </inertial>
      <visual>
        <origin xyz="0 0 0" rpy="0 0 0" />
        <geometry>
          <mesh filename="package://rr_robot_description/include/chassis/meshes/VacuumSheet/visual.STL" />
        </geometry>
        <material name="black">
          <color rgba="0.2 0.2 0.2 1" />
        </material>
      </visual>
      <!-- Collision of vacuum sheet is neglected -->
      <!--<collision>
        <origin xyz="0 0 0" rpy="0 0 0" />
        <geometry>
          <mesh filename="package://rr_robot_description/include/chassis/meshes/VacuumSheet/collision.STL" />
        </geometry>
      </collision> -->
    </link>
    <joint name="vacuum_sheet_joint" type="fixed">
      <origin xyz="0.55919 0. -0.145" rpy="0. 0. 1.5708" />
      <parent link="${name}" />
      <child link="vacuum_sheet" />
    </joint>

    <!-- ********************* Cameras ********************* -->

    <!-- left camera -->
    <link name="left_camera" />
    <joint name="left_camera_joint" type="fixed">
      <origin xyz="0.30684 0.27941 0.02105" rpy="1.16132 0.09568 2.25280" />
      <parent link="${name}" />
      <child link="left_camera" />
    </joint>

    <!-- top camera -->
    <link name="top_camera" />
    <joint name="top_camera_joint" type="fixed">
      <origin xyz="1.06522 0.08622 0.03725" rpy="0 0 0" />
      <parent link="${name}" />
      <child link="top_camera" />
    </joint>

    <!-- right camera -->
    <link name="right_camera" />
    <joint name="right_camera_joint" type="fixed">
      <origin xyz="0.30684 -0.27941 0.02105" rpy="-1.16132 0.09568 -2.25280" />
      <parent link="${name}" />
      <child link="right_camera" />
    </joint>

    <!-- ********************* Tool holders ********************* -->
    <xacro:include filename="$(find rr_robot_description)/include/chassis/urdf/tool_holder.xacro"/>
    <xacro:tool_holder_macro name="th0" parent="${name}" x_offset="0.95394" y_offset="0.0875" z_offset="0.12783" yaw="1.5708"/>
    <xacro:tool_holder_macro name="th1" parent="${name}" x_offset="0.95394" y_offset="-0.0875" z_offset="0.12783" yaw="1.5708"/>
    <xacro:tool_holder_macro name="th2" parent="${name}" x_offset="0.67894" y_offset="0.175" z_offset="0.12783" yaw="1.5708"/>
    <xacro:tool_holder_macro name="th3" parent="${name}" x_offset="0.67894" y_offset="0." z_offset="0.12783" yaw="1.5708"/>
    <xacro:tool_holder_macro name="th4" parent="${name}" x_offset="0.67894" y_offset="-0.175" z_offset="0.12783" yaw="1.5708"/>
    <xacro:tool_holder_macro name="th5" parent="${name}" x_offset="0.40394" y_offset="0.175" z_offset="0.12783" yaw="1.5708"/>
    <xacro:tool_holder_macro name="th6" parent="${name}" x_offset="0.40394" y_offset="0." z_offset="0.12783" yaw="1.5708"/>
    <xacro:tool_holder_macro name="th7" parent="${name}" x_offset="0.40394" y_offset="-0.175" z_offset="0.12783" yaw="1.5708"/>

  </xacro:macro>
</robot>
