<?xml version="1.0"?>
<robot xmlns:xacro="http://ros.org/wiki/xacro" name="chassis_macro">
  <xacro:macro name="chassis_macro" params="name parent_link x_offset:=0 y_offset:=0 z_offset:=0">
    <link name="${name}">
      <inertial>
        <origin xyz="0.45171 -1.9114E-06 -0.0060107" rpy="0 0 0" />
        <mass value="120.39" />
        <inertia ixx="0.44337" ixy="0.00087842" ixz="-0.12544" iyy="31.837" iyz="-2.5044E-05" izz="31.906" />
      </inertial>
      <visual>
        <origin xyz="0 0 0" rpy="0 0 0" />
        <geometry>
          <mesh filename="package://rr_robot_description/include/chassis/meshes/Chassis/visual.STL" />
        </geometry>
        <material name="rr_blue">
          <color rgba="0 0.62352941176 0.89019607843 1" />
        </material>
      </visual>
      <collision>
        <origin xyz="0 0 0" rpy="0 0 0" />
        <geometry>
          <mesh filename="package://rr_robot_description/include/chassis/meshes/Chassis/collision.STL" />
        </geometry>
      </collision>
    </link>

    <joint name="${parent_link}_to_${name}" type="fixed">
      <parent link="${parent_link}"/>
      <child link="${name}" />
      <origin xyz="${x_offset} ${y_offset} ${z_offset}" rpy="0 0 0" />
    </joint>

    <!-- ********************* Rope Drives ********************** -->

    <!-- TODO: add mass and inertia -->

    <link name="rope_drive_le">
      <inertial>
        <mass value="1" />
        <origin xyz="0 0 0" rpy="0 0 0" />
        <inertia ixx="0.002526666666667" ixy="0" ixz="0" iyy="0.002526666666667" iyz="0" izz="0.005"/>
      </inertial>
      <visual>
        <origin xyz="0 0 0" rpy="0 0 0" />
        <geometry>
          <mesh filename="package://rr_robot_description/include/chassis/meshes/RopeDrives/visual.STL" />
        </geometry>
        <material name="grey">
          <color rgba="0.4 0.4 0.4 1" />
        </material>
      </visual>
      <visual>
        <origin rpy="${pi/2} 0 0" xyz="0.035 0 0" />
        <geometry>
          <box size="0.005 0.10 0.005" />
        </geometry>
        <material name="Grey">
          <color rgba="0.6 0.6 0.6 1" />
        </material>
      </visual>
      <collision>
        <origin xyz="0 0 0" rpy="0 0 0" />
        <geometry>
          <mesh filename="package://rr_robot_description/include/chassis/meshes/RopeDrives/collision.STL" />
        </geometry>
      </collision>
    </link>
    <joint name="rope_drive_le_joint" type="continuous">
      <origin xyz="0.92999 0.24067 -0.0269" rpy="-0.09857 0.09857 -1.64405" />
      <axis rpy="0 0 0" xyz="1 0 0" />
      <limit effort="10000" velocity="1000" />
      <joint_properties damping="1.0" friction="1.0" />
      <parent link="${name}" />
      <child link="rope_drive_le" />
    </joint>

    <link name="rope_drive_te">
      <inertial>
        <mass value="1" />
        <origin xyz="0 0 0" rpy="0 0 0" />
        <inertia ixx="0.002526666666667" ixy="0" ixz="0" iyy="0.002526666666667" iyz="0" izz="0.005"/>
      </inertial>
      <visual>
        <origin xyz="0 0 0" rpy="0 0 0" />
        <geometry>
          <mesh filename="package://rr_robot_description/include/chassis/meshes/RopeDrives/visual.STL" />
        </geometry>
        <material name="grey">
          <color rgba="0.4 0.4 0.4 1" />
        </material>
      </visual>
      <visual>
        <origin rpy="${pi/2} 0 0" xyz="0.035 0 0" />
        <geometry>
          <box size="0.005 0.10 0.005" />
        </geometry>
        <material name="Grey">
          <color rgba="0.6 0.6 0.6 1" />
        </material>
      </visual>
      <collision>
        <origin xyz="0 0 0" rpy="0 0 0" />
        <geometry>
          <mesh filename="package://rr_robot_description/include/chassis/meshes/RopeDrives/collision.STL" />
        </geometry>
      </collision>
    </link>
    <joint name="rope_drive_te_joint" type="continuous">
      <origin xyz="0.92999 -0.24067 -0.0269" rpy="0.09857 0.09857 1.64405" />
      <axis rpy="0 0 0" xyz="1 0 0" />
      <limit effort="10000" velocity="1000" />
      <joint_properties damping="1.0" friction="1.0" />
      <parent link="${name}" />
      <child link="rope_drive_te" />
    </joint>

    <!-- ********************* Bottom Wheels ******************** -->

    <!-- TODO: add mass and inertia -->

    <link name="bot_wheel_le">
      <inertial>
        <mass value="1" />
        <origin xyz="0 0 0" rpy="0 0 0" />
        <inertia ixx="0.002526666666667" ixy="0" ixz="0" iyy="0.002526666666667" iyz="0" izz="0.005"/>
      </inertial>
      <visual>
        <origin xyz="0 0 0" rpy="0 0 0" />
        <geometry>
          <mesh filename="package://rr_robot_description/include/chassis/meshes/BottomWheels/visual.STL" />
        </geometry>
        <material name="grey">
          <color rgba="0.4 0.4 0.4 1" />
        </material>
      </visual>
      <collision>
        <origin xyz="0 0 0" rpy="0 0 0" />
        <geometry>
          <mesh filename="package://rr_robot_description/include/chassis/meshes/BottomWheels/collision.STL" />
        </geometry>
      </collision>
    </link>
    <joint name="bot_wheel_le_joint" type="fixed">
      <origin xyz="-0.0251 0.1615 -0.11818" rpy="0. 0. 1.5708" />
      <parent link="${name}" />
      <child link="bot_wheel_le" />
    </joint>

    <link name="bot_wheel_te">
      <inertial>
        <mass value="1" />
        <origin xyz="0 0 0" rpy="0 0 0" />
        <inertia ixx="0.002526666666667" ixy="0" ixz="0" iyy="0.002526666666667" iyz="0" izz="0.005"/>
      </inertial>
      <visual>
        <origin xyz="0 0 0" rpy="0 0 0" />
        <geometry>
          <mesh filename="package://rr_robot_description/include/chassis/meshes/BottomWheels/visual.STL" />
        </geometry>
        <material name="grey">
          <color rgba="0.4 0.4 0.4 1" />
        </material>
      </visual>
      <collision>
        <origin xyz="0 0 0" rpy="0 0 0" />
        <geometry>
          <mesh filename="package://rr_robot_description/include/chassis/meshes/BottomWheels/collision.STL" />
        </geometry>
      </collision>
    </link>
    <joint name="bot_wheel_te_joint" type="fixed">
      <origin xyz="-0.0251 -0.1615 -0.11818" rpy="0. 0. -1.5708" />
      <parent link="${name}" />
      <child link="bot_wheel_te" />
    </joint>

    <!-- ********************* Top Wheels *********************** -->

    <!-- TODO: add mass and inertia -->

    <link name="top_wheel_le">
      <inertial>
        <mass value="1" />
        <origin xyz="0 0 0" rpy="0 0 0" />
        <inertia ixx="0.002526666666667" ixy="0" ixz="0" iyy="0.002526666666667" iyz="0" izz="0.005"/>
      </inertial>
      <visual>
        <origin xyz="0 0 0" rpy="0 0 0" />
        <geometry>
          <mesh filename="package://rr_robot_description/include/chassis/meshes/TopWheels/visual.STL" />
        </geometry>
        <material name="grey">
          <color rgba="0.4 0.4 0.4 1" />
        </material>
      </visual>
      <collision>
        <origin xyz="0 0 0" rpy="0 0 0" />
        <geometry>
          <mesh filename="package://rr_robot_description/include/chassis/meshes/TopWheels/collision.STL" />
        </geometry>
      </collision>
    </link>
    <joint name="top_wheel_le_joint" type="revolute">
      <origin xyz="1.13039 0.12962 -0.1344" rpy="0. 0. 1.5708" />
      <axis rpy="0 0 0" xyz="0 0 1" />
      <limit lower="-0.20" upper="0.20" effort="10000" velocity="1000" />
      <joint_properties damping="1.0" friction="1.0" />
      <parent link="${name}" />
      <child link="top_wheel_le" />
    </joint>

    <link name="top_wheel_te">
      <inertial>
        <mass value="1" />
        <origin xyz="0 0 0" rpy="0 0 0" />
        <inertia ixx="0.002526666666667" ixy="0" ixz="0" iyy="0.002526666666667" iyz="0" izz="0.005"/>
      </inertial>
      <visual>
        <origin xyz="0 0 0" rpy="0 0 0" />
        <geometry>
          <mesh filename="package://rr_robot_description/include/chassis/meshes/TopWheels/visual.STL" />
        </geometry>
        <material name="grey">
          <color rgba="0.4 0.4 0.4 1" />
        </material>
      </visual>
      <collision>
        <origin xyz="0 0 0" rpy="0 0 0" />
        <geometry>
          <mesh filename="package://rr_robot_description/include/chassis/meshes/TopWheels/collision.STL" />
        </geometry>
      </collision>
    </link>
    <joint name="top_wheel_te_joint" type="revolute">
      <origin xyz="1.13039 -0.12962 -0.1344" rpy="0. 0. -1.5708" />
      <axis rpy="0 0 0" xyz="0 0 1" />
      <limit lower="-0.20" upper="0.20" effort="10000" velocity="1000" />
      <joint_properties damping="1.0" friction="1.0" />
      <parent link="${name}" />
      <child link="top_wheel_te" />
    </joint>

    <!-- ********************* Vacuum Sheet ********************* -->

    <!-- TODO: add mass and inertia -->

    <link name="vacuum_sheet">
      <inertial>
        <mass value="1" />
        <origin xyz="0 0 0" rpy="0 0 0" />
        <inertia ixx="0.002526666666667" ixy="0" ixz="0" iyy="0.002526666666667" iyz="0" izz="0.005"/>
      </inertial>
      <visual>
        <origin xyz="0 0 0" rpy="0 0 0" />
        <geometry>
          <mesh filename="package://rr_robot_description/include/chassis/meshes/VacuumSheet/visual.STL" />
        </geometry>
        <material name="black">
          <color rgba="0.2 0.2 0.2 1" />
        </material>
      </visual>
      <!-- Collision of vacuum sheet is neglected -->
      <!--<collision>
        <origin xyz="0 0 0" rpy="0 0 0" />
        <geometry>
          <mesh filename="package://rr_robot_description/include/chassis/meshes/VacuumSheet/collision.STL" />
        </geometry>
      </collision> -->
    </link>
    <joint name="vacuum_sheet_joint" type="fixed">
      <origin xyz="0.55919 0. -0.145" rpy="0. 0. 1.5708" />
      <parent link="${name}" />
      <child link="vacuum_sheet" />
    </joint>

    <!-- ********************* Cameras ********************* -->

    <!-- left camera -->
    <link name="left_camera" />
    <joint name="left_camera_joint" type="fixed">
      <origin xyz="0.30684 0.27941 0.02105" rpy="1.16132 0.09568 2.25280" />
      <parent link="${name}" />
      <child link="left_camera" />
    </joint>

    <!-- top camera -->
    <link name="top_camera" />
    <joint name="top_camera_joint" type="fixed">
      <origin xyz="1.06522 0.08622 0.03725" rpy="0 0 0" />
      <parent link="${name}" />
      <child link="top_camera" />
    </joint>

    <!-- right camera -->
    <link name="right_camera" />
    <joint name="right_camera_joint" type="fixed">
      <origin xyz="0.30684 -0.27941 0.02105" rpy="-1.16132 0.09568 -2.25280" />
      <parent link="${name}" />
      <child link="right_camera" />
    </joint>

    <!-- ********************* Tool holders ********************* -->
    <link name="th0" >
      <inertial>
        <mass value="0.1911" />
        <origin xyz="0 0 0" rpy="0 0 0" />
        <inertia ixx="0.01880039566" ixy="-0.00288516792" ixz="0.00164510501" iyy="0.00519681040" iyz="-0.00798447007" izz="0.01485438661"/>
      </inertial>
      <visual>
        <origin xyz="0 0 0" rpy="0 0 0" />
        <geometry>
          <mesh filename="package://rr_robot_description/include/chassis/meshes/ToolHolder/visual.STL" />
        </geometry>
        <material name="black">
          <color rgba="0.2 0.2 0.2 1" />
        </material>
      </visual>
      <collision>
        <origin xyz="0 0 0" rpy="0 0 0" />
        <geometry>
          <mesh filename="package://rr_robot_description/include/chassis/meshes/ToolHolder/collision.STL" />
        </geometry>
      </collision>
    </link>
    <joint name="th0_joint" type="fixed">
      <origin
        xyz="0.95394 0.0875 0.12783"
        rpy="-1.0611E-15 7.6478E-16 1.5708" />
      <parent link="${name}" />
      <child link="th0" />
    </joint>
    <link name="th1" >
      <inertial>
        <mass value="0.1911" />
        <origin xyz="0 0 0" rpy="0 0 0" />
        <inertia ixx="0.01880039566" ixy="-0.00288516792" ixz="0.00164510501" iyy="0.00519681040" iyz="-0.00798447007" izz="0.01485438661"/>
      </inertial>
      <visual>
        <origin xyz="0 0 0" rpy="0 0 0" />
        <geometry>
          <mesh filename="package://rr_robot_description/include/chassis/meshes/ToolHolder/visual.STL" />
        </geometry>
        <material name="black">
          <color rgba="0.2 0.2 0.2 1" />
        </material>
      </visual>
      <collision>
        <origin xyz="0 0 0" rpy="0 0 0" />
        <geometry>
          <mesh filename="package://rr_robot_description/include/chassis/meshes/ToolHolder/collision.STL" />
        </geometry>
      </collision>
    </link>
    <joint name="th1_joint" type="fixed">
      <origin
        xyz="0.95394 -0.0875 0.12783"
        rpy="-1.0611E-15 7.6478E-16 1.5708" />
      <parent link="${name}" />
      <child link="th1" />
    </joint>
    <link name="th2" >
      <inertial>
        <mass value="0.1911" />
        <origin xyz="0 0 0" rpy="0 0 0" />
        <inertia ixx="0.01880039566" ixy="-0.00288516792" ixz="0.00164510501" iyy="0.00519681040" iyz="-0.00798447007" izz="0.01485438661"/>
      </inertial>
      <visual>
        <origin xyz="0 0 0" rpy="0 0 0" />
        <geometry>
          <mesh filename="package://rr_robot_description/include/chassis/meshes/ToolHolder/visual.STL" />
        </geometry>
        <material name="black">
          <color rgba="0.2 0.2 0.2 1" />
        </material>
      </visual>
      <collision>
        <origin xyz="0 0 0" rpy="0 0 0" />
        <geometry>
          <mesh filename="package://rr_robot_description/include/chassis/meshes/ToolHolder/collision.STL" />
        </geometry>
      </collision>
    </link>
    <joint name="th2_joint" type="fixed">
      <origin
        xyz="0.67894 0.175 0.12783"
        rpy="-1.0611E-15 7.6478E-16 1.5708" />
      <parent link="${name}" />
      <child link="th2" />
    </joint>
    <link name="th3" >
      <inertial>
        <mass value="0.1911" />
        <origin xyz="0 0 0" rpy="0 0 0" />
        <inertia ixx="0.01880039566" ixy="-0.00288516792" ixz="0.00164510501" iyy="0.00519681040" iyz="-0.00798447007" izz="0.01485438661"/>
      </inertial>
      <visual>
        <origin xyz="0 0 0" rpy="0 0 0" />
        <geometry>
          <mesh filename="package://rr_robot_description/include/chassis/meshes/ToolHolder/visual.STL" />
        </geometry>
        <material name="black">
          <color rgba="0.2 0.2 0.2 1" />
        </material>
      </visual>
      <collision>
        <origin xyz="0 0 0" rpy="0 0 0" />
        <geometry>
          <mesh filename="package://rr_robot_description/include/chassis/meshes/ToolHolder/collision.STL" />
        </geometry>
      </collision>
    </link>
    <joint name="th3_joint" type="fixed">
      <origin
        xyz="0.67894 0 0.12783"
        rpy="-1.0611E-15 7.6478E-16 1.5708" />
      <parent link="${name}" />
      <child link="th3" />
    </joint>
    <link name="th4" >
      <inertial>
        <mass value="0.1911" />
        <origin xyz="0 0 0" rpy="0 0 0" />
        <inertia ixx="0.01880039566" ixy="-0.00288516792" ixz="0.00164510501" iyy="0.00519681040" iyz="-0.00798447007" izz="0.01485438661"/>
      </inertial>
      <visual>
        <origin xyz="0 0 0" rpy="0 0 0" />
        <geometry>
          <mesh filename="package://rr_robot_description/include/chassis/meshes/ToolHolder/visual.STL" />
        </geometry>
        <material name="black">
          <color rgba="0.2 0.2 0.2 1" />
        </material>
      </visual>
      <collision>
        <origin xyz="0 0 0" rpy="0 0 0" />
        <geometry>
          <mesh filename="package://rr_robot_description/include/chassis/meshes/ToolHolder/collision.STL" />
        </geometry>
      </collision>
    </link>
    <joint name="th4_joint" type="fixed">
      <origin
        xyz="0.67894 -0.175 0.12783"
        rpy="-1.0611E-15 7.6478E-16 1.5708" />
      <parent
        link="${name}" />
      <child
        link="th4" />
    </joint>
    <link name="th5" >
      <inertial>
        <mass value="0.1911" />
        <origin xyz="0 0 0" rpy="0 0 0" />
        <inertia ixx="0.01880039566" ixy="-0.00288516792" ixz="0.00164510501" iyy="0.00519681040" iyz="-0.00798447007" izz="0.01485438661"/>
      </inertial>
      <visual>
        <origin xyz="0 0 0" rpy="0 0 0" />
        <geometry>
          <mesh filename="package://rr_robot_description/include/chassis/meshes/ToolHolder/visual.STL" />
        </geometry>
        <material name="black">
          <color rgba="0.2 0.2 0.2 1" />
        </material>
      </visual>
      <collision>
        <origin xyz="0 0 0" rpy="0 0 0" />
        <geometry>
          <mesh filename="package://rr_robot_description/include/chassis/meshes/ToolHolder/collision.STL" />
        </geometry>
      </collision>
    </link>
    <joint name="th5_joint" type="fixed">
      <origin
        xyz="0.40394 0.175 0.12783"
        rpy="-1.0611E-15 7.6478E-16 1.5708" />
      <parent link="${name}" />
      <child link="th5" />
    </joint>
    <link name="th6" >
      <inertial>
        <mass value="0.1911" />
        <origin xyz="0 0 0" rpy="0 0 0" />
        <inertia ixx="0.01880039566" ixy="-0.00288516792" ixz="0.00164510501" iyy="0.00519681040" iyz="-0.00798447007" izz="0.01485438661"/>
      </inertial>
      <visual>
        <origin xyz="0 0 0" rpy="0 0 0" />
        <geometry>
          <mesh filename="package://rr_robot_description/include/chassis/meshes/ToolHolder/visual.STL" />
        </geometry>
        <material name="black">
          <color rgba="0.2 0.2 0.2 1" />
        </material>
      </visual>
      <collision>
        <origin xyz="0 0 0" rpy="0 0 0" />
        <geometry>
          <mesh filename="package://rr_robot_description/include/chassis/meshes/ToolHolder/collision.STL" />
        </geometry>
      </collision>
    </link>
    <joint name="th6_joint" type="fixed">
      <origin
        xyz="0.40394 0 0.12783"
        rpy="-1.0611E-15 7.6478E-16 1.5708" />
      <parent link="${name}" />
      <child link="th6" />
    </joint>
    <link name="th7" >
      <inertial>
        <mass value="0.1911" />
        <origin xyz="0 0 0" rpy="0 0 0" />
        <inertia ixx="0.01880039566" ixy="-0.00288516792" ixz="0.00164510501" iyy="0.00519681040" iyz="-0.00798447007" izz="0.01485438661"/>
      </inertial>
      <visual>
        <origin xyz="0 0 0" rpy="0 0 0" />
        <geometry>
          <mesh filename="package://rr_robot_description/include/chassis/meshes/ToolHolder/visual.STL" />
        </geometry>
        <material name="black">
          <color rgba="0.2 0.2 0.2 1" />
        </material>
      </visual>
      <collision>
        <origin xyz="0 0 0" rpy="0 0 0" />
        <geometry>
          <mesh filename="package://rr_robot_description/include/chassis/meshes/ToolHolder/collision.STL" />
        </geometry>
      </collision>
    </link>
    <joint name="th7_joint" type="fixed">
      <origin
        xyz="0.40394 -0.175 0.12783"
        rpy="-1.0611E-15 7.6478E-16 1.5708" />
      <parent link="${name}" />
      <child link="th7" />
    </joint>

  </xacro:macro>
</robot>
