<?xml version="1.0"?>
<robot xmlns:xacro="http://ros.org/wiki/xacro" name="rope_macro">

  <xacro:macro name="rope_macro" params="winch_name_no_postfix rope_l">
    <xacro:macro name="make_rope" params="te='true'">
      <xacro:if value="${te}" >
        <xacro:property name="yaw" value="3.14159" />
        <xacro:property name="postfix" value="te"/>
      </xacro:if>
      <xacro:unless value="${te}" >
        <xacro:property name="yaw" value="0" />
        <xacro:property name="postfix" value="le"/>
      </xacro:unless>
        <!-- Rope yaw -->
        <link name="rope_yaw_link_${postfix}">
          <inertial>
            <mass value="0.01" />
            <inertia ixx="0.01" ixy="0.0" ixz="0.0" iyy="0.01" iyz="0.0" izz="0.01" />
          </inertial>
      </link>
      <joint name="rope_yaw_${postfix}_joint" type="revolute">
        <axis xyz="0 0 1" />
        <limit lower="-0.5235" upper="0.5235" effort="100000" velocity="1000000"/>
        <parent link="${winch_name_no_postfix}_${postfix}"/>
        <child link="rope_yaw_link_${postfix}"/>
        <dynamics damping="0.5" />
      </joint>
  
      <!-- Rope pitch -->
        <link name="rope_pitch_link_${postfix}">
            <inertial>
              <mass value="0.01" />
              <inertia ixx="0.01" ixy="0.0" ixz="0.0" iyy="0.01" iyz="0.0" izz="0.01" />
            </inertial>
        </link>
        <joint name="rope_pitch_${postfix}_joint" type="revolute">
          <axis xyz="1 0 0" />
          <limit lower="-0.5235" upper="0.5235" effort="100000" velocity="1000000"/>
          <parent link="rope_yaw_link_${postfix}"/>
          <child link="rope_pitch_link_${postfix}"/>
          <dynamics damping="0.5" />
        </joint>
  
      <!-- rope prismatic joint (springed joint)-->
      <link name="rope_link_${postfix}">
          <inertial>
            <origin rpy="1.57 0 0" />
            <mass value="0.01" />
            <inertia ixx="0.01" ixy="0.0" ixz="0.0" iyy="0.01" iyz="0.0" izz="0.01" />
          </inertial>
          <visual>
            <origin rpy="1.57 0 0" />
            <geometry>
              <cylinder radius="0.01" length="0.5" />
            </geometry>
          </visual>
      </link>
  
      <joint name="rope_springed_joint_${postfix}" type="prismatic">
        <origin xyz="0 0 0.035" rpy="0 0 ${yaw}" />
        <axis xyz="0 1 0" />
        <limit lower="0" upper="${rope_l}" effort="100000" velocity="1000000"/>
        <parent link="rope_pitch_link_${postfix}"/>
        <child link="rope_link_${postfix}" />
        <dynamics damping="0.5" />
      </joint>
    </xacro:macro>
    
    <xacro:make_rope te="true" />
    <xacro:make_rope te="false" />
  </xacro:macro>
</robot>